[2023-12-09T17:46:55.162+0000] {taskinstance.py:1159} INFO - Dependencies all met for dep_context=non-requeueable deps ti=<TaskInstance: taskflow.upload_to_gcs manual__2023-12-09T17:46:49.501153+00:00 [queued]>
[2023-12-09T17:46:55.170+0000] {taskinstance.py:1159} INFO - Dependencies all met for dep_context=requeueable deps ti=<TaskInstance: taskflow.upload_to_gcs manual__2023-12-09T17:46:49.501153+00:00 [queued]>
[2023-12-09T17:46:55.171+0000] {taskinstance.py:1361} INFO - Starting attempt 1 of 1
[2023-12-09T17:46:55.189+0000] {taskinstance.py:1382} INFO - Executing <Task(LocalFilesystemToGCSOperator): upload_to_gcs> on 2023-12-09 17:46:49.501153+00:00
[2023-12-09T17:46:55.205+0000] {standard_task_runner.py:57} INFO - Started process 28677 to run task
[2023-12-09T17:46:55.209+0000] {standard_task_runner.py:84} INFO - Running: ['***', 'tasks', 'run', 'taskflow', 'upload_to_gcs', 'manual__2023-12-09T17:46:49.501153+00:00', '--job-id', '97', '--raw', '--subdir', 'DAGS_FOLDER/test_decorator.py', '--cfg-path', '/tmp/tmp9ruf5hwa']
[2023-12-09T17:46:55.212+0000] {standard_task_runner.py:85} INFO - Job 97: Subtask upload_to_gcs
[2023-12-09T17:46:55.255+0000] {task_command.py:416} INFO - Running <TaskInstance: taskflow.upload_to_gcs manual__2023-12-09T17:46:49.501153+00:00 [running]> on host 3de6e37e1218
[2023-12-09T17:46:55.356+0000] {taskinstance.py:1662} INFO - Exporting env vars: AIRFLOW_CTX_DAG_OWNER='***' AIRFLOW_CTX_DAG_ID='taskflow' AIRFLOW_CTX_TASK_ID='upload_to_gcs' AIRFLOW_CTX_EXECUTION_DATE='2023-12-09T17:46:49.501153+00:00' AIRFLOW_CTX_TRY_NUMBER='1' AIRFLOW_CTX_DAG_RUN_ID='manual__2023-12-09T17:46:49.501153+00:00'
[2023-12-09T17:46:55.366+0000] {connection.py:232} WARNING - Connection schemes (type: google_cloud_platform) shall not contain '_' according to RFC3986.
[2023-12-09T17:46:55.367+0000] {base.py:73} INFO - Using connection ID 'google_cloud_datastore_default' for task execution.
[2023-12-09T17:46:55.368+0000] {credentials_provider.py:353} INFO - Getting connection using `google.auth.default()` since no explicit credentials are provided.
[2023-12-09T17:46:55.450+0000] {taskinstance.py:1937} ERROR - Task failed with exception
Traceback (most recent call last):
  File "/home/airflow/.local/lib/python3.8/site-packages/airflow/providers/google/cloud/transfers/local_to_gcs.py", line 110, in execute
    hook.upload(
  File "/home/airflow/.local/lib/python3.8/site-packages/airflow/providers/google/cloud/hooks/gcs.py", line 556, in upload
    _call_with_retry(
  File "/home/airflow/.local/lib/python3.8/site-packages/airflow/providers/google/cloud/hooks/gcs.py", line 514, in _call_with_retry
    f()
  File "/home/airflow/.local/lib/python3.8/site-packages/google/cloud/storage/blob.py", line 2926, in upload_from_filename
    self._handle_filename_and_upload(
  File "/home/airflow/.local/lib/python3.8/site-packages/google/cloud/storage/blob.py", line 2794, in _handle_filename_and_upload
    with open(filename, "rb") as file_obj:
FileNotFoundError: [Errno 2] No such file or directory: 'Customers.csv'
[2023-12-09T17:46:55.465+0000] {taskinstance.py:1400} INFO - Marking task as FAILED. dag_id=taskflow, task_id=upload_to_gcs, execution_date=20231209T174649, start_date=20231209T174655, end_date=20231209T174655
[2023-12-09T17:46:55.474+0000] {standard_task_runner.py:104} ERROR - Failed to execute job 97 for task upload_to_gcs ([Errno 2] No such file or directory: 'Customers.csv'; 28677)
[2023-12-09T17:46:55.511+0000] {local_task_job_runner.py:228} INFO - Task exited with return code 1
[2023-12-09T17:46:55.533+0000] {taskinstance.py:2778} INFO - 0 downstream tasks scheduled from follow-on schedule check
