[2023-12-10T06:57:50.212+0000] {taskinstance.py:1159} INFO - Dependencies all met for dep_context=non-requeueable deps ti=<TaskInstance: taskflow.load_Categorie_to_bigquery manual__2023-12-10T06:57:11.931744+00:00 [queued]>
[2023-12-10T06:57:50.561+0000] {taskinstance.py:1159} INFO - Dependencies all met for dep_context=requeueable deps ti=<TaskInstance: taskflow.load_Categorie_to_bigquery manual__2023-12-10T06:57:11.931744+00:00 [queued]>
[2023-12-10T06:57:50.593+0000] {taskinstance.py:1361} INFO - Starting attempt 1 of 1
[2023-12-10T06:57:51.033+0000] {taskinstance.py:1382} INFO - Executing <Task(GCSToBigQueryOperator): load_Categorie_to_bigquery> on 2023-12-10 06:57:11.931744+00:00
[2023-12-10T06:57:51.122+0000] {standard_task_runner.py:57} INFO - Started process 1041 to run task
[2023-12-10T06:57:51.430+0000] {standard_task_runner.py:84} INFO - Running: ['***', 'tasks', 'run', 'taskflow', 'load_Categorie_to_bigquery', 'manual__2023-12-10T06:57:11.931744+00:00', '--job-id', '118', '--raw', '--subdir', 'DAGS_FOLDER/test_decorator.py', '--cfg-path', '/tmp/tmpcrc_eiso']
[2023-12-10T06:57:51.523+0000] {standard_task_runner.py:85} INFO - Job 118: Subtask load_Categorie_to_bigquery
[2023-12-10T06:57:52.535+0000] {task_command.py:416} INFO - Running <TaskInstance: taskflow.load_Categorie_to_bigquery manual__2023-12-10T06:57:11.931744+00:00 [running]> on host 580ab8862310
[2023-12-10T06:57:58.198+0000] {taskinstance.py:1662} INFO - Exporting env vars: AIRFLOW_CTX_DAG_OWNER='***' AIRFLOW_CTX_DAG_ID='taskflow' AIRFLOW_CTX_TASK_ID='load_Categorie_to_bigquery' AIRFLOW_CTX_EXECUTION_DATE='2023-12-10T06:57:11.931744+00:00' AIRFLOW_CTX_TRY_NUMBER='1' AIRFLOW_CTX_DAG_RUN_ID='manual__2023-12-10T06:57:11.931744+00:00'
[2023-12-10T06:57:58.896+0000] {connection.py:232} WARNING - Connection schemes (type: google_cloud_platform) shall not contain '_' according to RFC3986.
[2023-12-10T06:57:58.937+0000] {base.py:73} INFO - Using connection ID 'google_cloud_datastore_default' for task execution.
[2023-12-10T06:57:58.975+0000] {gcs_to_bigquery.py:376} INFO - Using existing BigQuery table for storing data...
[2023-12-10T06:57:59.061+0000] {credentials_provider.py:353} INFO - Getting connection using `google.auth.default()` since no explicit credentials are provided.
[2023-12-10T06:57:59.308+0000] {bigquery.py:2311} INFO - Project is not included in destination_project_dataset_table: dataset_for_dag_testing.Categorie; using project "northwind-qu"
[2023-12-10T06:57:59.312+0000] {gcs_to_bigquery.py:380} INFO - Executing: {'load': {'autodetect': True, 'createDisposition': 'CREATE_IF_NEEDED', 'destinationTable': {'projectId': 'northwind-qu', 'datasetId': 'dataset_for_dag_testing', 'tableId': 'Categorie'}, 'sourceFormat': 'CSV', 'sourceUris': ['gs://us-central1-test-env-b4f32c38-bucket/data/Categorie.csv'], 'writeDisposition': 'WRITE_TRUNCATE', 'ignoreUnknownValues': False, 'skipLeadingRows': 1, 'fieldDelimiter': ',', 'quote': None, 'allowQuotedNewlines': False, 'encoding': 'UTF-8'}}
[2023-12-10T06:57:59.327+0000] {bigquery.py:1595} INFO - Inserting job ***_taskflow_load_Categorie_to_bigquery_2023_12_10T06_57_11_931744_00_00_6f316d29d85e74781b0cc737b823a776
[2023-12-10T06:58:11.092+0000] {taskinstance.py:1937} ERROR - Task failed with exception
Traceback (most recent call last):
  File "/home/airflow/.local/lib/python3.8/site-packages/airflow/providers/google/cloud/transfers/gcs_to_bigquery.py", line 439, in execute
    job.result(timeout=self.result_timeout, retry=self.result_retry)
  File "/home/airflow/.local/lib/python3.8/site-packages/google/cloud/bigquery/job/base.py", line 922, in result
    return super(_AsyncJob, self).result(timeout=timeout, **kwargs)
  File "/home/airflow/.local/lib/python3.8/site-packages/google/api_core/future/polling.py", line 261, in result
    raise self._exception
google.api_core.exceptions.NotFound: 404 Not found: URI gs://us-central1-test-env-b4f32c38-bucket/data/Categorie.csv
[2023-12-10T06:58:11.552+0000] {taskinstance.py:1400} INFO - Marking task as FAILED. dag_id=taskflow, task_id=load_Categorie_to_bigquery, execution_date=20231210T065711, start_date=20231210T065750, end_date=20231210T065811
[2023-12-10T06:58:11.942+0000] {standard_task_runner.py:104} ERROR - Failed to execute job 118 for task load_Categorie_to_bigquery (404 Not found: URI gs://us-central1-test-env-b4f32c38-bucket/data/Categorie.csv; 1041)
[2023-12-10T06:58:12.016+0000] {local_task_job_runner.py:228} INFO - Task exited with return code 1
[2023-12-10T06:58:13.280+0000] {taskinstance.py:2778} INFO - 0 downstream tasks scheduled from follow-on schedule check
