[2023-12-03T21:35:53.962+0000] {taskinstance.py:1159} INFO - Dependencies all met for dep_context=non-requeueable deps ti=<TaskInstance: upload_local_to_gcs_python.upload_file manual__2023-12-03T21:35:51.975041+00:00 [queued]>
[2023-12-03T21:35:53.979+0000] {taskinstance.py:1159} INFO - Dependencies all met for dep_context=requeueable deps ti=<TaskInstance: upload_local_to_gcs_python.upload_file manual__2023-12-03T21:35:51.975041+00:00 [queued]>
[2023-12-03T21:35:53.980+0000] {taskinstance.py:1361} INFO - Starting attempt 1 of 2
[2023-12-03T21:35:54.001+0000] {taskinstance.py:1382} INFO - Executing <Task(LocalFilesystemToGCSOperator): upload_file> on 2023-12-03 21:35:51.975041+00:00
[2023-12-03T21:35:54.018+0000] {standard_task_runner.py:57} INFO - Started process 250 to run task
[2023-12-03T21:35:54.034+0000] {standard_task_runner.py:84} INFO - Running: ['***', 'tasks', 'run', 'upload_local_to_gcs_python', 'upload_file', 'manual__2023-12-03T21:35:51.975041+00:00', '--job-id', '12', '--raw', '--subdir', 'DAGS_FOLDER/local_to_GCS.py', '--cfg-path', '/tmp/tmpubx4pj5y']
[2023-12-03T21:35:54.040+0000] {standard_task_runner.py:85} INFO - Job 12: Subtask upload_file
[2023-12-03T21:35:54.266+0000] {task_command.py:416} INFO - Running <TaskInstance: upload_local_to_gcs_python.upload_file manual__2023-12-03T21:35:51.975041+00:00 [running]> on host e9db96b2fa13
[2023-12-03T21:35:54.454+0000] {taskinstance.py:1662} INFO - Exporting env vars: AIRFLOW_CTX_DAG_OWNER='your_owner' AIRFLOW_CTX_DAG_ID='upload_local_to_gcs_python' AIRFLOW_CTX_TASK_ID='upload_file' AIRFLOW_CTX_EXECUTION_DATE='2023-12-03T21:35:51.975041+00:00' AIRFLOW_CTX_TRY_NUMBER='1' AIRFLOW_CTX_DAG_RUN_ID='manual__2023-12-03T21:35:51.975041+00:00'
[2023-12-03T21:35:54.522+0000] {taskinstance.py:1937} ERROR - Task failed with exception
Traceback (most recent call last):
  File "/home/airflow/.local/lib/python3.8/site-packages/airflow/providers/google/cloud/transfers/local_to_gcs.py", line 90, in execute
    hook = GCSHook(
  File "/home/airflow/.local/lib/python3.8/site-packages/airflow/providers/google/cloud/hooks/gcs.py", line 164, in __init__
    super().__init__(
  File "/home/airflow/.local/lib/python3.8/site-packages/airflow/providers/google/common/hooks/base_google.py", line 242, in __init__
    self.extras: dict = self.get_connection(self.gcp_conn_id).extra_dejson
  File "/home/airflow/.local/lib/python3.8/site-packages/airflow/hooks/base.py", line 72, in get_connection
    conn = Connection.get_connection_from_secrets(conn_id)
  File "/home/airflow/.local/lib/python3.8/site-packages/airflow/models/connection.py", line 477, in get_connection_from_secrets
    raise AirflowNotFoundException(f"The conn_id `{conn_id}` isn't defined")
airflow.exceptions.AirflowNotFoundException: The conn_id `google_cloud_default` isn't defined
[2023-12-03T21:35:54.529+0000] {taskinstance.py:1400} INFO - Marking task as UP_FOR_RETRY. dag_id=upload_local_to_gcs_python, task_id=upload_file, execution_date=20231203T213551, start_date=20231203T213553, end_date=20231203T213554
[2023-12-03T21:35:54.547+0000] {standard_task_runner.py:104} ERROR - Failed to execute job 12 for task upload_file (The conn_id `google_cloud_default` isn't defined; 250)
[2023-12-03T21:35:54.583+0000] {local_task_job_runner.py:228} INFO - Task exited with return code 1
[2023-12-03T21:35:54.615+0000] {taskinstance.py:2778} INFO - 0 downstream tasks scheduled from follow-on schedule check
