[2023-12-03T22:15:52.661+0000] {taskinstance.py:1159} INFO - Dependencies all met for dep_context=non-requeueable deps ti=<TaskInstance: test-dag.transfer_gcs_to_bq manual__2023-12-03T22:15:43.741589+00:00 [queued]>
[2023-12-03T22:15:52.672+0000] {taskinstance.py:1159} INFO - Dependencies all met for dep_context=requeueable deps ti=<TaskInstance: test-dag.transfer_gcs_to_bq manual__2023-12-03T22:15:43.741589+00:00 [queued]>
[2023-12-03T22:15:52.672+0000] {taskinstance.py:1361} INFO - Starting attempt 1 of 3
[2023-12-03T22:15:52.688+0000] {taskinstance.py:1382} INFO - Executing <Task(GCSToBigQueryOperator): transfer_gcs_to_bq> on 2023-12-03 22:15:43.741589+00:00
[2023-12-03T22:15:52.704+0000] {standard_task_runner.py:57} INFO - Started process 1372 to run task
[2023-12-03T22:15:52.712+0000] {standard_task_runner.py:84} INFO - Running: ['***', 'tasks', 'run', 'test-dag', 'transfer_gcs_to_bq', 'manual__2023-12-03T22:15:43.741589+00:00', '--job-id', '16', '--raw', '--subdir', 'DAGS_FOLDER/GCS_to_BQ.py', '--cfg-path', '/tmp/tmphuqjzb4u']
[2023-12-03T22:15:52.725+0000] {standard_task_runner.py:85} INFO - Job 16: Subtask transfer_gcs_to_bq
[2023-12-03T22:15:52.921+0000] {task_command.py:416} INFO - Running <TaskInstance: test-dag.transfer_gcs_to_bq manual__2023-12-03T22:15:43.741589+00:00 [running]> on host e9db96b2fa13
[2023-12-03T22:15:53.040+0000] {taskinstance.py:1662} INFO - Exporting env vars: AIRFLOW_CTX_DAG_OWNER='phungquan' AIRFLOW_CTX_DAG_ID='test-dag' AIRFLOW_CTX_TASK_ID='transfer_gcs_to_bq' AIRFLOW_CTX_EXECUTION_DATE='2023-12-03T22:15:43.741589+00:00' AIRFLOW_CTX_TRY_NUMBER='1' AIRFLOW_CTX_DAG_RUN_ID='manual__2023-12-03T22:15:43.741589+00:00'
[2023-12-03T22:15:53.055+0000] {connection.py:232} WARNING - Connection schemes (type: google_cloud_platform) shall not contain '_' according to RFC3986.
[2023-12-03T22:15:53.057+0000] {base.py:73} INFO - Using connection ID 'google_cloud_default' for task execution.
[2023-12-03T22:15:53.059+0000] {gcs_to_bigquery.py:376} INFO - Using existing BigQuery table for storing data...
[2023-12-03T22:15:53.061+0000] {credentials_provider.py:353} INFO - Getting connection using `google.auth.default()` since no explicit credentials are provided.
[2023-12-03T22:15:56.072+0000] {_metadata.py:139} WARNING - Compute Engine Metadata server unavailable on attempt 1 of 3. Reason: timed out
[2023-12-03T22:15:59.086+0000] {_metadata.py:139} WARNING - Compute Engine Metadata server unavailable on attempt 2 of 3. Reason: timed out
[2023-12-03T22:15:59.090+0000] {_metadata.py:139} WARNING - Compute Engine Metadata server unavailable on attempt 3 of 3. Reason: [Errno 111] Connection refused
[2023-12-03T22:15:59.092+0000] {_default.py:338} WARNING - Authentication failed using Compute Engine authentication due to unavailable metadata server.
[2023-12-03T22:15:59.095+0000] {taskinstance.py:1937} ERROR - Task failed with exception
Traceback (most recent call last):
  File "/home/airflow/.local/lib/python3.8/site-packages/airflow/providers/google/cloud/transfers/gcs_to_bigquery.py", line 377, in execute
    self.configuration = self._use_existing_table()
  File "/home/airflow/.local/lib/python3.8/site-packages/airflow/providers/google/cloud/transfers/gcs_to_bigquery.py", line 578, in _use_existing_table
    default_project_id=self.hook.project_id,
  File "/home/airflow/.local/lib/python3.8/site-packages/airflow/providers/google/common/hooks/base_google.py", line 361, in project_id
    _, project_id = self.get_credentials_and_project_id()
  File "/home/airflow/.local/lib/python3.8/site-packages/airflow/providers/google/common/hooks/base_google.py", line 273, in get_credentials_and_project_id
    credentials, project_id = get_credentials_and_project_id(
  File "/home/airflow/.local/lib/python3.8/site-packages/airflow/providers/google/cloud/utils/credentials_provider.py", line 362, in get_credentials_and_project_id
    return _CredentialProvider(*args, **kwargs).get_credentials_and_project()
  File "/home/airflow/.local/lib/python3.8/site-packages/airflow/providers/google/cloud/utils/credentials_provider.py", line 243, in get_credentials_and_project
    credentials, project_id = self._get_credentials_using_adc()
  File "/home/airflow/.local/lib/python3.8/site-packages/airflow/providers/google/cloud/utils/credentials_provider.py", line 348, in _get_credentials_using_adc
    credentials, project_id = google.auth.default(scopes=self.scopes)
  File "/home/airflow/.local/lib/python3.8/site-packages/google/auth/_default.py", line 691, in default
    raise exceptions.DefaultCredentialsError(_CLOUD_SDK_MISSING_CREDENTIALS)
google.auth.exceptions.DefaultCredentialsError: Your default credentials were not found. To set up Application Default Credentials, see https://cloud.google.com/docs/authentication/external/set-up-adc for more information.
[2023-12-03T22:15:59.150+0000] {taskinstance.py:1400} INFO - Marking task as UP_FOR_RETRY. dag_id=test-dag, task_id=transfer_gcs_to_bq, execution_date=20231203T221543, start_date=20231203T221552, end_date=20231203T221559
[2023-12-03T22:15:59.174+0000] {standard_task_runner.py:104} ERROR - Failed to execute job 16 for task transfer_gcs_to_bq (Your default credentials were not found. To set up Application Default Credentials, see https://cloud.google.com/docs/authentication/external/set-up-adc for more information.; 1372)
[2023-12-03T22:15:59.226+0000] {local_task_job_runner.py:228} INFO - Task exited with return code 1
[2023-12-03T22:15:59.271+0000] {taskinstance.py:2778} INFO - 0 downstream tasks scheduled from follow-on schedule check
