[2023-12-07T09:44:12.665+0000] {taskinstance.py:1159} INFO - Dependencies all met for dep_context=non-requeueable deps ti=<TaskInstance: upload_local_to_gcs_python.upload_file manual__2023-12-07T09:44:10.857986+00:00 [queued]>
[2023-12-07T09:44:12.671+0000] {taskinstance.py:1159} INFO - Dependencies all met for dep_context=requeueable deps ti=<TaskInstance: upload_local_to_gcs_python.upload_file manual__2023-12-07T09:44:10.857986+00:00 [queued]>
[2023-12-07T09:44:12.671+0000] {taskinstance.py:1361} INFO - Starting attempt 1 of 0
[2023-12-07T09:44:12.680+0000] {taskinstance.py:1382} INFO - Executing <Task(LocalFilesystemToGCSOperator): upload_file> on 2023-12-07 09:44:10.857986+00:00
[2023-12-07T09:44:12.687+0000] {standard_task_runner.py:57} INFO - Started process 581 to run task
[2023-12-07T09:44:12.694+0000] {standard_task_runner.py:84} INFO - Running: ['***', 'tasks', 'run', 'upload_local_to_gcs_python', 'upload_file', 'manual__2023-12-07T09:44:10.857986+00:00', '--job-id', '55', '--raw', '--subdir', 'DAGS_FOLDER/local_to_GCS.py', '--cfg-path', '/tmp/tmpm221t676']
[2023-12-07T09:44:12.702+0000] {standard_task_runner.py:85} INFO - Job 55: Subtask upload_file
[2023-12-07T09:44:12.756+0000] {task_command.py:416} INFO - Running <TaskInstance: upload_local_to_gcs_python.upload_file manual__2023-12-07T09:44:10.857986+00:00 [running]> on host 3de6e37e1218
[2023-12-07T09:44:12.856+0000] {taskinstance.py:1662} INFO - Exporting env vars: AIRFLOW_CTX_DAG_OWNER='your_owner' AIRFLOW_CTX_DAG_ID='upload_local_to_gcs_python' AIRFLOW_CTX_TASK_ID='upload_file' AIRFLOW_CTX_EXECUTION_DATE='2023-12-07T09:44:10.857986+00:00' AIRFLOW_CTX_TRY_NUMBER='1' AIRFLOW_CTX_DAG_RUN_ID='manual__2023-12-07T09:44:10.857986+00:00'
[2023-12-07T09:44:12.877+0000] {connection.py:232} WARNING - Connection schemes (type: google_cloud_platform) shall not contain '_' according to RFC3986.
[2023-12-07T09:44:12.878+0000] {base.py:73} INFO - Using connection ID 'google_cloud_default' for task execution.
[2023-12-07T09:44:12.880+0000] {credentials_provider.py:353} INFO - Getting connection using `google.auth.default()` since no explicit credentials are provided.
[2023-12-07T09:44:15.943+0000] {gcs.py:517} ERROR - Upload attempt of object: Customers.csv from Customers.csv has failed. Attempt: 1, max 1.
[2023-12-07T09:44:15.949+0000] {taskinstance.py:1937} ERROR - Task failed with exception
Traceback (most recent call last):
  File "/home/airflow/.local/lib/python3.8/site-packages/google/cloud/storage/blob.py", line 2604, in _prep_and_do_upload
    created_json = self._do_upload(
  File "/home/airflow/.local/lib/python3.8/site-packages/google/cloud/storage/blob.py", line 2410, in _do_upload
    response = self._do_multipart_upload(
  File "/home/airflow/.local/lib/python3.8/site-packages/google/cloud/storage/blob.py", line 1923, in _do_multipart_upload
    response = upload.transmit(
  File "/home/airflow/.local/lib/python3.8/site-packages/google/resumable_media/requests/upload.py", line 153, in transmit
    return _request_helpers.wait_and_retry(
  File "/home/airflow/.local/lib/python3.8/site-packages/google/resumable_media/requests/_request_helpers.py", line 155, in wait_and_retry
    response = func()
  File "/home/airflow/.local/lib/python3.8/site-packages/google/resumable_media/requests/upload.py", line 149, in retriable_request
    self._process_response(result)
  File "/home/airflow/.local/lib/python3.8/site-packages/google/resumable_media/_upload.py", line 125, in _process_response
    _helpers.require_status_code(response, (http.client.OK,), self._get_status_code)
  File "/home/airflow/.local/lib/python3.8/site-packages/google/resumable_media/_helpers.py", line 108, in require_status_code
    raise common.InvalidResponse(
google.resumable_media.common.InvalidResponse: ('Request failed with status code', 404, 'Expected one of', 200)

During handling of the above exception, another exception occurred:

Traceback (most recent call last):
  File "/home/airflow/.local/lib/python3.8/site-packages/airflow/providers/google/cloud/transfers/local_to_gcs.py", line 110, in execute
    hook.upload(
  File "/home/airflow/.local/lib/python3.8/site-packages/airflow/providers/google/cloud/hooks/gcs.py", line 556, in upload
    _call_with_retry(
  File "/home/airflow/.local/lib/python3.8/site-packages/airflow/providers/google/cloud/hooks/gcs.py", line 524, in _call_with_retry
    raise e
  File "/home/airflow/.local/lib/python3.8/site-packages/airflow/providers/google/cloud/hooks/gcs.py", line 514, in _call_with_retry
    f()
  File "/home/airflow/.local/lib/python3.8/site-packages/google/cloud/storage/blob.py", line 2926, in upload_from_filename
    self._handle_filename_and_upload(
  File "/home/airflow/.local/lib/python3.8/site-packages/google/cloud/storage/blob.py", line 2796, in _handle_filename_and_upload
    self._prep_and_do_upload(
  File "/home/airflow/.local/lib/python3.8/site-packages/google/cloud/storage/blob.py", line 2622, in _prep_and_do_upload
    _raise_from_invalid_response(exc)
  File "/home/airflow/.local/lib/python3.8/site-packages/google/cloud/storage/blob.py", line 4778, in _raise_from_invalid_response
    raise exceptions.from_http_status(response.status_code, message, response=response)
google.api_core.exceptions.NotFound: 404 POST https://storage.googleapis.com/upload/storage/v1/b/us-central1-test-env-b4f32c38-bucket/data/o?uploadType=multipart: Not Found: ('Request failed with status code', 404, 'Expected one of', <HTTPStatus.OK: 200>)
[2023-12-07T09:44:15.984+0000] {taskinstance.py:1400} INFO - Marking task as FAILED. dag_id=upload_local_to_gcs_python, task_id=upload_file, execution_date=20231207T094410, start_date=20231207T094412, end_date=20231207T094415
[2023-12-07T09:44:16.003+0000] {standard_task_runner.py:104} ERROR - Failed to execute job 55 for task upload_file (404 POST https://storage.googleapis.com/upload/storage/v1/b/us-central1-test-env-b4f32c38-bucket/data/o?uploadType=multipart: Not Found: ('Request failed with status code', 404, 'Expected one of', <HTTPStatus.OK: 200>); 581)
[2023-12-07T09:44:16.054+0000] {local_task_job_runner.py:228} INFO - Task exited with return code 1
[2023-12-07T09:44:16.079+0000] {taskinstance.py:2778} INFO - 0 downstream tasks scheduled from follow-on schedule check
