[2023-12-09T12:30:02.737+0000] {taskinstance.py:1159} INFO - Dependencies all met for dep_context=non-requeueable deps ti=<TaskInstance: taskflow.upload_to_gcs manual__2023-12-09T12:30:00.120066+00:00 [queued]>
[2023-12-09T12:30:02.744+0000] {taskinstance.py:1159} INFO - Dependencies all met for dep_context=requeueable deps ti=<TaskInstance: taskflow.upload_to_gcs manual__2023-12-09T12:30:00.120066+00:00 [queued]>
[2023-12-09T12:30:02.745+0000] {taskinstance.py:1361} INFO - Starting attempt 1 of 1
[2023-12-09T12:30:02.754+0000] {taskinstance.py:1382} INFO - Executing <Task(LocalFilesystemToGCSOperator): upload_to_gcs> on 2023-12-09 12:30:00.120066+00:00
[2023-12-09T12:30:02.759+0000] {standard_task_runner.py:57} INFO - Started process 14139 to run task
[2023-12-09T12:30:02.764+0000] {standard_task_runner.py:84} INFO - Running: ['***', 'tasks', 'run', 'taskflow', 'upload_to_gcs', 'manual__2023-12-09T12:30:00.120066+00:00', '--job-id', '80', '--raw', '--subdir', 'DAGS_FOLDER/test_decorator.py', '--cfg-path', '/tmp/tmpcfo0kc21']
[2023-12-09T12:30:02.770+0000] {standard_task_runner.py:85} INFO - Job 80: Subtask upload_to_gcs
[2023-12-09T12:30:02.806+0000] {task_command.py:416} INFO - Running <TaskInstance: taskflow.upload_to_gcs manual__2023-12-09T12:30:00.120066+00:00 [running]> on host 3de6e37e1218
[2023-12-09T12:30:02.884+0000] {taskinstance.py:1662} INFO - Exporting env vars: AIRFLOW_CTX_DAG_OWNER='***' AIRFLOW_CTX_DAG_ID='taskflow' AIRFLOW_CTX_TASK_ID='upload_to_gcs' AIRFLOW_CTX_EXECUTION_DATE='2023-12-09T12:30:00.120066+00:00' AIRFLOW_CTX_TRY_NUMBER='1' AIRFLOW_CTX_DAG_RUN_ID='manual__2023-12-09T12:30:00.120066+00:00'
[2023-12-09T12:30:02.891+0000] {connection.py:232} WARNING - Connection schemes (type: google_cloud_platform) shall not contain '_' according to RFC3986.
[2023-12-09T12:30:02.892+0000] {base.py:73} INFO - Using connection ID 'google_cloud_datastore_default' for task execution.
[2023-12-09T12:30:02.893+0000] {credentials_provider.py:353} INFO - Getting connection using `google.auth.default()` since no explicit credentials are provided.
[2023-12-09T12:30:03.858+0000] {gcs.py:517} ERROR - Upload attempt of object: data/Customers.csv from data/Customers.csv has failed. Attempt: 1, max 1.
[2023-12-09T12:30:03.861+0000] {taskinstance.py:1937} ERROR - Task failed with exception
Traceback (most recent call last):
  File "/home/airflow/.local/lib/python3.8/site-packages/google/cloud/storage/blob.py", line 2604, in _prep_and_do_upload
    created_json = self._do_upload(
  File "/home/airflow/.local/lib/python3.8/site-packages/google/cloud/storage/blob.py", line 2410, in _do_upload
    response = self._do_multipart_upload(
  File "/home/airflow/.local/lib/python3.8/site-packages/google/cloud/storage/blob.py", line 1923, in _do_multipart_upload
    response = upload.transmit(
  File "/home/airflow/.local/lib/python3.8/site-packages/google/resumable_media/requests/upload.py", line 153, in transmit
    return _request_helpers.wait_and_retry(
  File "/home/airflow/.local/lib/python3.8/site-packages/google/resumable_media/requests/_request_helpers.py", line 155, in wait_and_retry
    response = func()
  File "/home/airflow/.local/lib/python3.8/site-packages/google/resumable_media/requests/upload.py", line 149, in retriable_request
    self._process_response(result)
  File "/home/airflow/.local/lib/python3.8/site-packages/google/resumable_media/_upload.py", line 125, in _process_response
    _helpers.require_status_code(response, (http.client.OK,), self._get_status_code)
  File "/home/airflow/.local/lib/python3.8/site-packages/google/resumable_media/_helpers.py", line 108, in require_status_code
    raise common.InvalidResponse(
google.resumable_media.common.InvalidResponse: ('Request failed with status code', 400, 'Expected one of', 200)

During handling of the above exception, another exception occurred:

Traceback (most recent call last):
  File "/home/airflow/.local/lib/python3.8/site-packages/airflow/providers/google/cloud/transfers/local_to_gcs.py", line 110, in execute
    hook.upload(
  File "/home/airflow/.local/lib/python3.8/site-packages/airflow/providers/google/cloud/hooks/gcs.py", line 556, in upload
    _call_with_retry(
  File "/home/airflow/.local/lib/python3.8/site-packages/airflow/providers/google/cloud/hooks/gcs.py", line 524, in _call_with_retry
    raise e
  File "/home/airflow/.local/lib/python3.8/site-packages/airflow/providers/google/cloud/hooks/gcs.py", line 514, in _call_with_retry
    f()
  File "/home/airflow/.local/lib/python3.8/site-packages/google/cloud/storage/blob.py", line 2926, in upload_from_filename
    self._handle_filename_and_upload(
  File "/home/airflow/.local/lib/python3.8/site-packages/google/cloud/storage/blob.py", line 2796, in _handle_filename_and_upload
    self._prep_and_do_upload(
  File "/home/airflow/.local/lib/python3.8/site-packages/google/cloud/storage/blob.py", line 2622, in _prep_and_do_upload
    _raise_from_invalid_response(exc)
  File "/home/airflow/.local/lib/python3.8/site-packages/google/cloud/storage/blob.py", line 4778, in _raise_from_invalid_response
    raise exceptions.from_http_status(response.status_code, message, response=response)
google.api_core.exceptions.BadRequest: 400 POST https://storage.googleapis.com/upload/storage/v1/b/us-central1-test-env-%20-bucket/o?uploadType=multipart: {
  "error": {
    "code": 400,
    "message": "Invalid bucket name: 'us-central1-test-env- -bucket'",
    "errors": [
      {
        "message": "Invalid bucket name: 'us-central1-test-env- -bucket'",
        "domain": "global",
        "reason": "invalid"
      }
    ]
  }
}
: ('Request failed with status code', 400, 'Expected one of', <HTTPStatus.OK: 200>)
[2023-12-09T12:30:03.891+0000] {taskinstance.py:1400} INFO - Marking task as FAILED. dag_id=taskflow, task_id=upload_to_gcs, execution_date=20231209T123000, start_date=20231209T123002, end_date=20231209T123003
[2023-12-09T12:30:03.905+0000] {standard_task_runner.py:104} ERROR - Failed to execute job 80 for task upload_to_gcs (400 POST https://storage.googleapis.com/upload/storage/v1/b/us-central1-test-env-%20-bucket/o?uploadType=multipart: {
  "error": {
    "code": 400,
    "message": "Invalid bucket name: 'us-central1-test-env- -bucket'",
    "errors": [
      {
        "message": "Invalid bucket name: 'us-central1-test-env- -bucket'",
        "domain": "global",
        "reason": "invalid"
      }
    ]
  }
}
: ('Request failed with status code', 400, 'Expected one of', <HTTPStatus.OK: 200>); 14139)
[2023-12-09T12:30:03.930+0000] {local_task_job_runner.py:228} INFO - Task exited with return code 1
[2023-12-09T12:30:03.953+0000] {taskinstance.py:2778} INFO - 0 downstream tasks scheduled from follow-on schedule check
