[2023-12-07T09:42:35.360+0000] {taskinstance.py:1159} INFO - Dependencies all met for dep_context=non-requeueable deps ti=<TaskInstance: upload_local_to_gcs_python.upload_file manual__2023-12-07T09:42:33.698962+00:00 [queued]>
[2023-12-07T09:42:35.366+0000] {taskinstance.py:1159} INFO - Dependencies all met for dep_context=requeueable deps ti=<TaskInstance: upload_local_to_gcs_python.upload_file manual__2023-12-07T09:42:33.698962+00:00 [queued]>
[2023-12-07T09:42:35.367+0000] {taskinstance.py:1361} INFO - Starting attempt 1 of 0
[2023-12-07T09:42:35.376+0000] {taskinstance.py:1382} INFO - Executing <Task(LocalFilesystemToGCSOperator): upload_file> on 2023-12-07 09:42:33.698962+00:00
[2023-12-07T09:42:35.384+0000] {standard_task_runner.py:57} INFO - Started process 497 to run task
[2023-12-07T09:42:35.388+0000] {standard_task_runner.py:84} INFO - Running: ['***', 'tasks', 'run', 'upload_local_to_gcs_python', 'upload_file', 'manual__2023-12-07T09:42:33.698962+00:00', '--job-id', '54', '--raw', '--subdir', 'DAGS_FOLDER/local_to_GCS.py', '--cfg-path', '/tmp/tmppdtkmi_b']
[2023-12-07T09:42:35.391+0000] {standard_task_runner.py:85} INFO - Job 54: Subtask upload_file
[2023-12-07T09:42:35.468+0000] {task_command.py:416} INFO - Running <TaskInstance: upload_local_to_gcs_python.upload_file manual__2023-12-07T09:42:33.698962+00:00 [running]> on host 3de6e37e1218
[2023-12-07T09:42:35.583+0000] {taskinstance.py:1662} INFO - Exporting env vars: AIRFLOW_CTX_DAG_OWNER='your_owner' AIRFLOW_CTX_DAG_ID='upload_local_to_gcs_python' AIRFLOW_CTX_TASK_ID='upload_file' AIRFLOW_CTX_EXECUTION_DATE='2023-12-07T09:42:33.698962+00:00' AIRFLOW_CTX_TRY_NUMBER='1' AIRFLOW_CTX_DAG_RUN_ID='manual__2023-12-07T09:42:33.698962+00:00'
[2023-12-07T09:42:35.597+0000] {connection.py:232} WARNING - Connection schemes (type: google_cloud_platform) shall not contain '_' according to RFC3986.
[2023-12-07T09:42:35.599+0000] {base.py:73} INFO - Using connection ID 'google_cloud_default' for task execution.
[2023-12-07T09:42:35.600+0000] {taskinstance.py:1937} ERROR - Task failed with exception
Traceback (most recent call last):
  File "/home/airflow/.local/lib/python3.8/site-packages/airflow/providers/google/cloud/transfers/local_to_gcs.py", line 97, in execute
    raise FileNotFoundError(self.src)
FileNotFoundError: /opt/***/data/northwind_gitRepo/tables/Customers.csv
[2023-12-07T09:42:35.610+0000] {taskinstance.py:1400} INFO - Marking task as FAILED. dag_id=upload_local_to_gcs_python, task_id=upload_file, execution_date=20231207T094233, start_date=20231207T094235, end_date=20231207T094235
[2023-12-07T09:42:35.620+0000] {standard_task_runner.py:104} ERROR - Failed to execute job 54 for task upload_file (/opt/***/data/northwind_gitRepo/tables/Customers.csv; 497)
[2023-12-07T09:42:35.645+0000] {local_task_job_runner.py:228} INFO - Task exited with return code 1
[2023-12-07T09:42:35.662+0000] {taskinstance.py:2778} INFO - 0 downstream tasks scheduled from follow-on schedule check
