[2024-01-17T12:48:22.623+0000] {taskinstance.py:1957} INFO - Dependencies all met for dep_context=non-requeueable deps ti=<TaskInstance: sql_example.train_model manual__2024-01-17T12:48:20.187260+00:00 [queued]>
[2024-01-17T12:48:22.630+0000] {taskinstance.py:1957} INFO - Dependencies all met for dep_context=requeueable deps ti=<TaskInstance: sql_example.train_model manual__2024-01-17T12:48:20.187260+00:00 [queued]>
[2024-01-17T12:48:22.630+0000] {taskinstance.py:2171} INFO - Starting attempt 1 of 0
[2024-01-17T12:48:22.641+0000] {taskinstance.py:2192} INFO - Executing <Task(PythonOperator): train_model> on 2024-01-17 12:48:20.187260+00:00
[2024-01-17T12:48:22.673+0000] {standard_task_runner.py:60} INFO - Started process 2022 to run task
[2024-01-17T12:48:22.679+0000] {standard_task_runner.py:87} INFO - Running: ['***', 'tasks', 'run', 'sql_example', 'train_model', 'manual__2024-01-17T12:48:20.187260+00:00', '--job-id', '28', '--raw', '--subdir', 'DAGS_FOLDER/data_transform_BQ.py', '--cfg-path', '/tmp/tmpiyo20hyl']
[2024-01-17T12:48:22.684+0000] {standard_task_runner.py:88} INFO - Job 28: Subtask train_model
[2024-01-17T12:48:22.736+0000] {task_command.py:423} INFO - Running <TaskInstance: sql_example.train_model manual__2024-01-17T12:48:20.187260+00:00 [running]> on host fafdf46f827b
[2024-01-17T12:48:22.816+0000] {taskinstance.py:2481} INFO - Exporting env vars: AIRFLOW_CTX_DAG_OWNER='phungquan' AIRFLOW_CTX_DAG_ID='sql_example' AIRFLOW_CTX_TASK_ID='train_model' AIRFLOW_CTX_EXECUTION_DATE='2024-01-17T12:48:20.187260+00:00' AIRFLOW_CTX_TRY_NUMBER='1' AIRFLOW_CTX_DAG_RUN_ID='manual__2024-01-17T12:48:20.187260+00:00'
[2024-01-17T12:48:23.843+0000] {taskinstance.py:2699} ERROR - Task failed with exception
Traceback (most recent call last):
  File "/home/airflow/.local/lib/python3.8/site-packages/airflow/models/taskinstance.py", line 433, in _execute_task
    result = execute_callable(context=context, **execute_callable_kwargs)
  File "/home/airflow/.local/lib/python3.8/site-packages/airflow/operators/python.py", line 199, in execute
    return_value = self.execute_callable()
  File "/home/airflow/.local/lib/python3.8/site-packages/airflow/operators/python.py", line 216, in execute_callable
    return self.python_callable(*self.op_args, **self.op_kwargs)
  File "/opt/airflow/dags/data_transform_BQ.py", line 142, in model_training
    train_model()
  File "/opt/airflow/dags/clustering.py", line 18, in train_model
    df = query_job.to_dataframe()
  File "/home/airflow/.local/lib/python3.8/site-packages/google/cloud/bigquery/job/query.py", line 1890, in to_dataframe
    query_result = wait_for_query(self, progress_bar_type, max_results=max_results)
  File "/home/airflow/.local/lib/python3.8/site-packages/google/cloud/bigquery/_tqdm_helpers.py", line 104, in wait_for_query
    return query_job.result(max_results=max_results)
  File "/home/airflow/.local/lib/python3.8/site-packages/google/cloud/bigquery/job/query.py", line 1595, in result
    do_get_result()
  File "/home/airflow/.local/lib/python3.8/site-packages/google/api_core/retry.py", line 372, in retry_wrapped_func
    return retry_target(
  File "/home/airflow/.local/lib/python3.8/site-packages/google/api_core/retry.py", line 207, in retry_target
    result = target()
  File "/home/airflow/.local/lib/python3.8/site-packages/google/cloud/bigquery/job/query.py", line 1584, in do_get_result
    super(QueryJob, self).result(retry=retry, timeout=timeout)
  File "/home/airflow/.local/lib/python3.8/site-packages/google/cloud/bigquery/job/base.py", line 952, in result
    return super(_AsyncJob, self).result(timeout=timeout, **kwargs)
  File "/home/airflow/.local/lib/python3.8/site-packages/google/api_core/future/polling.py", line 261, in result
    raise self._exception
google.api_core.exceptions.BadRequest: 400 SELECT list expression references column Recency which is neither grouped nor aggregated at [1:20]

Location: us-central1
Job ID: 67c07d0f-803d-4db1-b1b4-a44432958db8

[2024-01-17T12:48:23.874+0000] {taskinstance.py:1138} INFO - Marking task as FAILED. dag_id=sql_example, task_id=train_model, execution_date=20240117T124820, start_date=20240117T124822, end_date=20240117T124823
[2024-01-17T12:48:23.888+0000] {standard_task_runner.py:107} ERROR - Failed to execute job 28 for task train_model (400 SELECT list expression references column Recency which is neither grouped nor aggregated at [1:20]

Location: us-central1
Job ID: 67c07d0f-803d-4db1-b1b4-a44432958db8
; 2022)
[2024-01-17T12:48:23.912+0000] {local_task_job_runner.py:234} INFO - Task exited with return code 1
[2024-01-17T12:48:23.927+0000] {taskinstance.py:3281} INFO - 0 downstream tasks scheduled from follow-on schedule check
