[2024-01-09T07:11:59.327+0000] {taskinstance.py:1159} INFO - Dependencies all met for dep_context=non-requeueable deps ti=<TaskInstance: sql_example.train_model manual__2024-01-09T07:11:00.254716+00:00 [queued]>
[2024-01-09T07:11:59.334+0000] {taskinstance.py:1159} INFO - Dependencies all met for dep_context=requeueable deps ti=<TaskInstance: sql_example.train_model manual__2024-01-09T07:11:00.254716+00:00 [queued]>
[2024-01-09T07:11:59.334+0000] {taskinstance.py:1361} INFO - Starting attempt 1 of 0
[2024-01-09T07:11:59.343+0000] {taskinstance.py:1382} INFO - Executing <Task(PythonOperator): train_model> on 2024-01-09 07:11:00.254716+00:00
[2024-01-09T07:11:59.351+0000] {standard_task_runner.py:57} INFO - Started process 1285 to run task
[2024-01-09T07:11:59.355+0000] {standard_task_runner.py:84} INFO - Running: ['***', 'tasks', 'run', 'sql_example', 'train_model', 'manual__2024-01-09T07:11:00.254716+00:00', '--job-id', '255', '--raw', '--subdir', 'DAGS_FOLDER/data_transform_BQ.py', '--cfg-path', '/tmp/tmp8eiv2b_n']
[2024-01-09T07:11:59.358+0000] {standard_task_runner.py:85} INFO - Job 255: Subtask train_model
[2024-01-09T07:11:59.398+0000] {task_command.py:416} INFO - Running <TaskInstance: sql_example.train_model manual__2024-01-09T07:11:00.254716+00:00 [running]> on host 812d78d3a260
[2024-01-09T07:11:59.474+0000] {taskinstance.py:1662} INFO - Exporting env vars: AIRFLOW_CTX_DAG_OWNER='phungquan' AIRFLOW_CTX_DAG_ID='sql_example' AIRFLOW_CTX_TASK_ID='train_model' AIRFLOW_CTX_EXECUTION_DATE='2024-01-09T07:11:00.254716+00:00' AIRFLOW_CTX_TRY_NUMBER='1' AIRFLOW_CTX_DAG_RUN_ID='manual__2024-01-09T07:11:00.254716+00:00'
[2024-01-09T07:12:00.678+0000] {taskinstance.py:1937} ERROR - Task failed with exception
Traceback (most recent call last):
  File "/home/airflow/.local/lib/python3.8/site-packages/airflow/operators/python.py", line 192, in execute
    return_value = self.execute_callable()
  File "/home/airflow/.local/lib/python3.8/site-packages/airflow/operators/python.py", line 209, in execute_callable
    return self.python_callable(*self.op_args, **self.op_kwargs)
  File "/opt/airflow/dags/data_transform_BQ.py", line 99, in model_training
    train_model()
  File "/opt/airflow/dags/clustering.py", line 19, in train_model
    df = query_job.to_dataframe()
  File "/home/airflow/.local/lib/python3.8/site-packages/google/cloud/bigquery/job/query.py", line 1859, in to_dataframe
    query_result = wait_for_query(self, progress_bar_type, max_results=max_results)
  File "/home/airflow/.local/lib/python3.8/site-packages/google/cloud/bigquery/_tqdm_helpers.py", line 104, in wait_for_query
    return query_job.result(max_results=max_results)
  File "/home/airflow/.local/lib/python3.8/site-packages/google/cloud/bigquery/job/query.py", line 1580, in result
    do_get_result()
  File "/home/airflow/.local/lib/python3.8/site-packages/google/api_core/retry.py", line 366, in retry_wrapped_func
    return retry_target(
  File "/home/airflow/.local/lib/python3.8/site-packages/google/api_core/retry.py", line 204, in retry_target
    return target()
  File "/home/airflow/.local/lib/python3.8/site-packages/google/cloud/bigquery/job/query.py", line 1570, in do_get_result
    super(QueryJob, self).result(retry=retry, timeout=timeout)
  File "/home/airflow/.local/lib/python3.8/site-packages/google/cloud/bigquery/job/base.py", line 922, in result
    return super(_AsyncJob, self).result(timeout=timeout, **kwargs)
  File "/home/airflow/.local/lib/python3.8/site-packages/google/api_core/future/polling.py", line 261, in result
    raise self._exception
google.api_core.exceptions.NotFound: 404 Not found: Dataset northwind-qu:LanhDataset was not found in location US

Location: US
Job ID: 81662790-517c-49da-8f6d-f43f5e1bfc07

[2024-01-09T07:12:00.709+0000] {taskinstance.py:1400} INFO - Marking task as FAILED. dag_id=sql_example, task_id=train_model, execution_date=20240109T071100, start_date=20240109T071159, end_date=20240109T071200
[2024-01-09T07:12:00.722+0000] {standard_task_runner.py:104} ERROR - Failed to execute job 255 for task train_model (404 Not found: Dataset northwind-qu:LanhDataset was not found in location US

Location: US
Job ID: 81662790-517c-49da-8f6d-f43f5e1bfc07
; 1285)
[2024-01-09T07:12:00.759+0000] {local_task_job_runner.py:228} INFO - Task exited with return code 1
[2024-01-09T07:12:00.779+0000] {taskinstance.py:2778} INFO - 0 downstream tasks scheduled from follow-on schedule check
