[2023-12-04T08:26:03.112+0000] {taskinstance.py:1159} INFO - Dependencies all met for dep_context=non-requeueable deps ti=<TaskInstance: test-dag.transfer_gcs_to_bq manual__2023-12-04T08:26:00.663754+00:00 [queued]>
[2023-12-04T08:26:03.119+0000] {taskinstance.py:1159} INFO - Dependencies all met for dep_context=requeueable deps ti=<TaskInstance: test-dag.transfer_gcs_to_bq manual__2023-12-04T08:26:00.663754+00:00 [queued]>
[2023-12-04T08:26:03.119+0000] {taskinstance.py:1361} INFO - Starting attempt 1 of 0
[2023-12-04T08:26:03.130+0000] {taskinstance.py:1382} INFO - Executing <Task(GCSToBigQueryOperator): transfer_gcs_to_bq> on 2023-12-04 08:26:00.663754+00:00
[2023-12-04T08:26:03.143+0000] {standard_task_runner.py:57} INFO - Started process 1257 to run task
[2023-12-04T08:26:03.150+0000] {standard_task_runner.py:84} INFO - Running: ['***', 'tasks', 'run', 'test-dag', 'transfer_gcs_to_bq', 'manual__2023-12-04T08:26:00.663754+00:00', '--job-id', '24', '--raw', '--subdir', 'DAGS_FOLDER/GCS_to_BQ.py', '--cfg-path', '/tmp/tmpxxtg50op']
[2023-12-04T08:26:03.155+0000] {standard_task_runner.py:85} INFO - Job 24: Subtask transfer_gcs_to_bq
[2023-12-04T08:26:03.208+0000] {task_command.py:416} INFO - Running <TaskInstance: test-dag.transfer_gcs_to_bq manual__2023-12-04T08:26:00.663754+00:00 [running]> on host 053a042197f6
[2023-12-04T08:26:03.295+0000] {taskinstance.py:1662} INFO - Exporting env vars: AIRFLOW_CTX_DAG_OWNER='phungquan' AIRFLOW_CTX_DAG_ID='test-dag' AIRFLOW_CTX_TASK_ID='transfer_gcs_to_bq' AIRFLOW_CTX_EXECUTION_DATE='2023-12-04T08:26:00.663754+00:00' AIRFLOW_CTX_TRY_NUMBER='1' AIRFLOW_CTX_DAG_RUN_ID='manual__2023-12-04T08:26:00.663754+00:00'
[2023-12-04T08:26:03.303+0000] {connection.py:232} WARNING - Connection schemes (type: google_cloud_platform) shall not contain '_' according to RFC3986.
[2023-12-04T08:26:03.304+0000] {base.py:73} INFO - Using connection ID 'google_cloud_default' for task execution.
[2023-12-04T08:26:03.305+0000] {gcs_to_bigquery.py:376} INFO - Using existing BigQuery table for storing data...
[2023-12-04T08:26:03.306+0000] {credentials_provider.py:353} INFO - Getting connection using `google.auth.default()` since no explicit credentials are provided.
[2023-12-04T08:26:06.314+0000] {_metadata.py:139} WARNING - Compute Engine Metadata server unavailable on attempt 1 of 3. Reason: timed out
[2023-12-04T08:26:06.324+0000] {_metadata.py:139} WARNING - Compute Engine Metadata server unavailable on attempt 2 of 3. Reason: [Errno 111] Connection refused
[2023-12-04T08:26:06.325+0000] {_metadata.py:139} WARNING - Compute Engine Metadata server unavailable on attempt 3 of 3. Reason: [Errno 111] Connection refused
[2023-12-04T08:26:06.326+0000] {_default.py:338} WARNING - Authentication failed using Compute Engine authentication due to unavailable metadata server.
[2023-12-04T08:26:06.327+0000] {taskinstance.py:1937} ERROR - Task failed with exception
Traceback (most recent call last):
  File "/home/airflow/.local/lib/python3.8/site-packages/airflow/providers/google/cloud/transfers/gcs_to_bigquery.py", line 377, in execute
    self.configuration = self._use_existing_table()
  File "/home/airflow/.local/lib/python3.8/site-packages/airflow/providers/google/cloud/transfers/gcs_to_bigquery.py", line 578, in _use_existing_table
    default_project_id=self.hook.project_id,
  File "/home/airflow/.local/lib/python3.8/site-packages/airflow/providers/google/common/hooks/base_google.py", line 361, in project_id
    _, project_id = self.get_credentials_and_project_id()
  File "/home/airflow/.local/lib/python3.8/site-packages/airflow/providers/google/common/hooks/base_google.py", line 273, in get_credentials_and_project_id
    credentials, project_id = get_credentials_and_project_id(
  File "/home/airflow/.local/lib/python3.8/site-packages/airflow/providers/google/cloud/utils/credentials_provider.py", line 362, in get_credentials_and_project_id
    return _CredentialProvider(*args, **kwargs).get_credentials_and_project()
  File "/home/airflow/.local/lib/python3.8/site-packages/airflow/providers/google/cloud/utils/credentials_provider.py", line 243, in get_credentials_and_project
    credentials, project_id = self._get_credentials_using_adc()
  File "/home/airflow/.local/lib/python3.8/site-packages/airflow/providers/google/cloud/utils/credentials_provider.py", line 348, in _get_credentials_using_adc
    credentials, project_id = google.auth.default(scopes=self.scopes)
  File "/home/airflow/.local/lib/python3.8/site-packages/google/auth/_default.py", line 691, in default
    raise exceptions.DefaultCredentialsError(_CLOUD_SDK_MISSING_CREDENTIALS)
google.auth.exceptions.DefaultCredentialsError: Your default credentials were not found. To set up Application Default Credentials, see https://cloud.google.com/docs/authentication/external/set-up-adc for more information.
[2023-12-04T08:26:06.351+0000] {taskinstance.py:1400} INFO - Marking task as FAILED. dag_id=test-dag, task_id=transfer_gcs_to_bq, execution_date=20231204T082600, start_date=20231204T082603, end_date=20231204T082606
[2023-12-04T08:26:06.367+0000] {standard_task_runner.py:104} ERROR - Failed to execute job 24 for task transfer_gcs_to_bq (Your default credentials were not found. To set up Application Default Credentials, see https://cloud.google.com/docs/authentication/external/set-up-adc for more information.; 1257)
[2023-12-04T08:26:06.387+0000] {local_task_job_runner.py:228} INFO - Task exited with return code 1
[2023-12-04T08:26:06.418+0000] {taskinstance.py:2778} INFO - 0 downstream tasks scheduled from follow-on schedule check
