[2023-12-03T21:48:03.514+0000] {taskinstance.py:1159} INFO - Dependencies all met for dep_context=non-requeueable deps ti=<TaskInstance: upload_local_to_gcs_python.upload_file manual__2023-12-03T21:46:59.941702+00:00 [queued]>
[2023-12-03T21:48:03.522+0000] {taskinstance.py:1159} INFO - Dependencies all met for dep_context=requeueable deps ti=<TaskInstance: upload_local_to_gcs_python.upload_file manual__2023-12-03T21:46:59.941702+00:00 [queued]>
[2023-12-03T21:48:03.523+0000] {taskinstance.py:1361} INFO - Starting attempt 2 of 2
[2023-12-03T21:48:03.534+0000] {taskinstance.py:1382} INFO - Executing <Task(LocalFilesystemToGCSOperator): upload_file> on 2023-12-03 21:46:59.941702+00:00
[2023-12-03T21:48:03.548+0000] {standard_task_runner.py:57} INFO - Started process 561 to run task
[2023-12-03T21:48:03.556+0000] {standard_task_runner.py:84} INFO - Running: ['***', 'tasks', 'run', 'upload_local_to_gcs_python', 'upload_file', 'manual__2023-12-03T21:46:59.941702+00:00', '--job-id', '15', '--raw', '--subdir', 'DAGS_FOLDER/local_to_GCS.py', '--cfg-path', '/tmp/tmpjt38macg']
[2023-12-03T21:48:03.561+0000] {standard_task_runner.py:85} INFO - Job 15: Subtask upload_file
[2023-12-03T21:48:03.622+0000] {task_command.py:416} INFO - Running <TaskInstance: upload_local_to_gcs_python.upload_file manual__2023-12-03T21:46:59.941702+00:00 [running]> on host e9db96b2fa13
[2023-12-03T21:48:03.720+0000] {taskinstance.py:1662} INFO - Exporting env vars: AIRFLOW_CTX_DAG_OWNER='your_owner' AIRFLOW_CTX_DAG_ID='upload_local_to_gcs_python' AIRFLOW_CTX_TASK_ID='upload_file' AIRFLOW_CTX_EXECUTION_DATE='2023-12-03T21:46:59.941702+00:00' AIRFLOW_CTX_TRY_NUMBER='2' AIRFLOW_CTX_DAG_RUN_ID='manual__2023-12-03T21:46:59.941702+00:00'
[2023-12-03T21:48:03.742+0000] {connection.py:232} WARNING - Connection schemes (type: google_cloud_platform) shall not contain '_' according to RFC3986.
[2023-12-03T21:48:03.744+0000] {base.py:73} INFO - Using connection ID 'google_cloud_default' for task execution.
[2023-12-03T21:48:03.745+0000] {taskinstance.py:1937} ERROR - Task failed with exception
Traceback (most recent call last):
  File "/home/airflow/.local/lib/python3.8/site-packages/airflow/providers/google/cloud/transfers/local_to_gcs.py", line 97, in execute
    raise FileNotFoundError(self.src)
FileNotFoundError: /Users/phunghongquan/Documents/học kì 5/DataWarehouse/northwind_gitRepo/northwind_gitRepo/tables/Customers.csv
[2023-12-03T21:48:03.757+0000] {taskinstance.py:1400} INFO - Marking task as FAILED. dag_id=upload_local_to_gcs_python, task_id=upload_file, execution_date=20231203T214659, start_date=20231203T214803, end_date=20231203T214803
[2023-12-03T21:48:03.771+0000] {standard_task_runner.py:104} ERROR - Failed to execute job 15 for task upload_file (/Users/phunghongquan/Documents/học kì 5/DataWarehouse/northwind_gitRepo/northwind_gitRepo/tables/Customers.csv; 561)
[2023-12-03T21:48:03.780+0000] {local_task_job_runner.py:228} INFO - Task exited with return code 1
[2023-12-03T21:48:03.804+0000] {taskinstance.py:2778} INFO - 0 downstream tasks scheduled from follow-on schedule check
